Workbook

Sheet Data
A1: Data
A3: No | B3: Kode | C3: Tahun | D3: Total Aset | E3: Total Aset n-1 | F3: Current Asset (Aset Lancar) | G3: Current Liabilities (Hutang Lancar) | H3: Total Liabilitas | I3: Total Ekuitas | J3: Laba Bersih | K3: Deviden
A4: 1 | B4: ICBP | C4: 2018 | D4: 34367153 | E4: 31619514 | F4: 14121568 | G4: 7235398 | H4: 11660003 | I4: 22707150 | J4: 4658781 | K4: 2565620
C5: 2019 | D5: 38709314 | E5: 34367153 | F5: 16624925 | G5: 6556359 | H5: 12038210 | I5: 26671104 | J5: 5360029 | K5: 1597681
C6: 2020 | D6: 103588325 | E6: 38709314 | F6: 20716223 | G6: 9176164 | H6: 53270272 | I6: 50318053 | J6: 7418574 | K6: 2507310
C7: 2021 | D7: 118015311 | E7: 103588325 | F7: 33997637 | G7: 18896133 | H7: 63074704 | I7: 54940607 | J7: 7911943 | K7: 2507310
C8: 2022 | D8: 115305536 | E8: 118015311 | F8: 31070365 | G8: 10033935 | H8: 57832529 | I8: 57473007 | J8: 5722194 | K8: 2507310
A9: 2 | B9: INDF | C9: 2018 | D9: 96537796 | E9: 88400877 | F9: 33272618 | G9: 31204102 | H9: 46620996 | I9: 49916800 | J9: 4961851 | K9: 2651689
C10: 2019 | D10: 96198559 | E10: 96537796 | F10: 31403445 | G10: 24686862 | H10: 41996071 | I10: 54202488 | J10: 5902729 | K10: 1501453
C11: 2020 | D11: 163136516 | E11: 96198559 | F11: 38418238 | G11: 27975875 | H11: 83998472 | I11: 79138044 | J11: 8752066 | K11: 2440959
C12: 2021 | D12: 179271840 | E12: 163136516 | F12: 54183399 | G12: 40403404 | H12: 92285331 | I12: 86986509 | J12: 11229695 | K12: 2440959
C13: 2022 | D13: 180433300 | E13: 179271840 | F13: 54876668 | G13: 30725942 | H13: 86810262 | I13: 93623038 | J13: 9192569 | K13: 2440959
A14: 3 | B14: MYOR | C14: 2018 | D14: 17591706426634 | E14: 14915849800251 | F14: 12647858727872 | G14: 4764510387113 | H14: 9049161944940 | I14: 8542544481694 | J14: 1760434280304 | K14: 603684892575
C15: 2019 | D15: 19037918806473 | E15: 17591706426634 | F15: 12776102781513 | G15: 3714359539201 | H15: 9125978611155 | I15: 9911940195318 | J15: 2051404206764 | K15: 648402292025
C16: 2020 | D16: 19777500514550 | E16: 19037918806473 | F16: 12838729162094 | G16: 3475323711943 | H16: 8506032464592 | I16: 11271468049958 | J16: 2098168514645 | K16: 670760991750
C17: 2021 | D17: 19917653265528 | E17: 19777500514550 | F17: 12969783874643 | G17: 5570773468770 | H17: 8557621869393 | I17: 11360031396135 | J17: 1211052647953 | K17: 1162652385700
C18: 2022 | D18: 22276160695411 | E18: 19917653265528 | F18: 14772623976128 | G18: 5636627301308 | H18: 9441466604896 | I18: 12834694090515 | J18: 1970064538149 | K18: 469532694225
A19: 4 | B19: GOOD | C19: 2018 | D19: 4212408305683 | E19: 3564218091628 | F19: 1570545769306 | G19: 1328163043500 | H19: 1722999829003 | I19: 2489408476680 | J19: 425481597110 | K19: 183082141237
C20: 2019 | D20: 5063067672414 | E20: 4212408305683 | F20: 1999886108743 | G20: 1303881731637 | H20: 2297546907499 | I20: 2765520764915 | J20: 435766359480 | K20: 132379748022
C21: 2020 | D21: 6570969641033 | E21: 5063067672414 | F21: 2314323530275 | G21: 1321529767664 | H21: 3676532851880 | I21: 2894436789153 | J21: 245103761907 | K21: 213786027325
C22: 2021 | D22: 6766602280143 | E22: 6570969641033 | F22: 2613436417820 | G22: 1771339531925 | H22: 3724365876731 | I22: 3042236403412 | J22: 492637672186 | K22: 131923972638
C23: 2022 | D23: 7327371934290 | E23: 6766602280143 | F23: 3194327374948 | G23: 1835096804319 | H23: 3975927432106 | I23: 3351444502184 | J23: 521714035585 | K23: 221508548952
A24: 5 | B24: ROTI | C24: 2018 | D24: 4393810380883 | E24: 4559573709411 | F24: 1876409299238 | G24: 525422150049 | H24: 1476909260772 | I24: 2916901120111 | J24: 127171436363 | K24: 36005365328
C25: 2019 | D25: 4682083844951 | E25: 4393810380883 | F25: 1874411044438 | G25: 1106938318565 | H25: 1589486465854 | I25: 3092597379097 | J25: 236518557420 | K25: 59724779679
C26: 2020 | D26: 4452166671985 | E26: 4682083844951 | F26: 1549617329468 | G26: 404567270700 | H26: 1224495624254 | I26: 3227671047731 | J26: 168610282478 | K26: 149528741987
C27: 2021 | D27: 4191284422677 | E27: 4452166671985 | F27: 1282057210341 | G27: 483213195704 | H27: 1321693219911 | I27: 2869591202766 | J27: 283602993676 | K27: 297289648543
C28: 2022 | D28: 4130321616083 | E28: 4191284422677 | F28: 1285672230703 | G28: 612417576293 | H28: 1449163077319 | I28: 2681158538764 | J28: 432247722254 | K28: 346139578657
A29: 6 | B29: DLTA | C29: 2018 | D29: 1523517170 | E29: 1340842765 | F29: 1384227944 | G29: 192299843 | H29: 239353356 | I29: 1284163814 | J29: 338129985 | K29: 208171353
C30: 2019 | D30: 1425983722 | E30: 1523517170 | F30: 1292805083 | G30: 160587363 | H30: 212420390 | I30: 1213563332 | J30: 317815177 | K30: 382134244
C31: 2020 | D31: 1225580913 | E31: 1425983722 | F31: 1103831856 | G31: 147207676 | H31: 205681950 | I31: 1019898963 | J31: 123465762 | K31: 311711537
C32: 2021 | D32: 1308722065 | E32: 1225580913 | F32: 1174393432 | G32: 244206806 | H32: 298548048 | I32: 1010174017 | J32: 187992998 | K32: 199764743
C33: 2022 | D33: 1307186367 | E33: 1308722065 | F33: 1165412820 | G33: 255354186 | H33: 306410502 | I33: 1000775865 | J33: 230065807 | K33: 239785159
A34: 7 | B34: SKLT | C34: 2018 | D34: 747293725435 | E34: 636284210210 | F34: 356735670030 | G34: 291349105535 | H34: 408057718435 | I34: 339236007000 | J34: 31954131252 | K34: 4351665150
C35: 2019 | D35: 790845543826 | E35: 747293725435 | F35: 378352247338 | G35: 293281364781 | H35: 410463595860 | I35: 380381947966 | J35: 44943627900 | K35: 5594998050
C36: 2020 | D36: 773863042440 | E36: 790845543826 | F36: 379723220668 | G36: 247102759160 | H36: 366908471713 | I36: 406954570727 | J36: 42520246722 | K36: 9324996750
C37: 2021 | D37: 889125250792 | E37: 773863042440 | F37: 433383441542 | G37: 241664687612 | H37: 347288021564 | I37: 541837229228 | J37: 84524160228 | K37: 9324996750
C38: 2022 | D38: 1033289474829 | E38: 889125250792 | F38: 543799195487 | G38: 333670108915 | H38: 442535947408 | I38: 590753527421 | J38: 74865302076 | K38: 29841405600
A39: 8 | B39: CEKA | C39: 2018 | D39: 1168956042706 | E39: 1392636444501 | F39: 809166450672 | G39: 158255592250 | H39: 192308466864 | I39: 976647575842 | J39: 92649656775 | K39: 59500000000
C40: 2019 | D40: 1393079542074 | E40: 1168956042706 | F40: 1067652078121 | G40: 222440530626 | H40: 261784845240 | I40: 1131294696834 | J40: 215459200242 | K40: 59500000000
C41: 2020 | D41: 1566673828068 | E41: 1393079542074 | F41: 1266586465994 | G41: 271641005590 | H41: 305958833204 | I41: 1260714994864 | J41: 181812593992 | K41: 59500000000
...

Sheet X1
A1: Struktur Modal (X1)
A3: No | B3: Kode | C3: Tahun | D3: Total Liabilitas | E3: Total Ekuitas | F3: Struktur Modal (X1)
A4: 1 | B4: ICBP | C4: 2018 | D4: 11660003 | E4: 22707150 | F4: =D4/E4 -> 0.51349478
C5: 2019 | D5: 12038210 | E5: 26671104 | F5: =D5/E5 -> 0.45135777
C6: 2020 | D6: 53270272 | E6: 50318053 | F6: =D6/E6 -> 1.0586712
C7: 2021 | D7: 63074704 | E7: 54940607 | F7: =D7/E7 -> 1.1480526
C8: 2022 | D8: 57832529 | E8: 57473007 | F8: =D8/E8 -> 1.0062555
A9: 2 | B9: INDF | C9: 2018 | D9: 46620996 | E9: 49916800 | F9: =D9/E9 -> 0.93397405
C10: 2019 | D10: 41996071 | E10: 54202488 | F10: =D10/E10 -> 0.77479969
C11: 2020 | D11: 83998472 | E11: 79138044 | F11: =D11/E11 -> 1.0614171
C12: 2021 | D12: 92285331 | E12: 86986509 | F12: =D12/E12 -> 1.0609154
C13: 2022 | D13: 86810262 | E13: 93623038 | F13: =D13/E13 -> 0.92723184
A14: 3 | B14: MYOR | C14: 2018 | D14: 9049161944940 | E14: 8542544481694 | F14: =D14/E14 -> 1.0593052
C15: 2019 | D15: 9125978611155 | E15: 9911940195318 | F15: =D15/E15 -> 0.92070558
C16: 2020 | D16: 8506032464592 | E16: 11271468049958 | F16: =D16/E16 -> 0.75465169
C17: 2021 | D17: 8557621869393 | E17: 11360031396135 | F17: =D17/E17 -> 0.7533097
C18: 2022 | D18: 9441466604896 | E18: 12834694090515 | F18: =D18/E18 -> 0.7356207
A19: 4 | B19: GOOD | C19: 2018 | D19: 1722999829003 | E19: 2489408476680 | F19: =D19/E19 -> 0.69213223
C20: 2019 | D20: 2297546907499 | E20: 2765520764915 | F20: =D20/E20 -> 0.83078274
C21: 2020 | D21: 3676532851880 | E21: 2894436789153 | F21: =D21/E21 -> 1.2702066
C22: 2021 | D22: 3724365876731 | E22: 3042236403412 | F22: =D22/E22 -> 1.2242197
C23: 2022 | D23: 3975927432106 | E23: 3351444502184 | F23: =D23/E23 -> 1.1863325
A24: 5 | B24: ROTI | C24: 2018 | D24: 1476909260772 | E24: 2916901120111 | F24: =D24/E24 -> 0.50632819
C25: 2019 | D25: 1589486465854 | E25: 3092597379097 | F25: =D25/E25 -> 0.51396489
C26: 2020 | D26: 1224495624254 | E26: 3227671047731 | F26: =D26/E26 -> 0.37937436
C27: 2021 | D27: 1321693219911 | E27: 2869591202766 | F27: =D27/E27 -> 0.46058589
C28: 2022 | D28: 1449163077319 | E28: 2681158538764 | F28: =D28/E28 -> 0.54049884
A29: 6 | B29: DLTA | C29: 2018 | D29: 239353356 | E29: 1284163814 | F29: =D29/E29 -> 0.18638849
C30: 2019 | D30: 212420390 | E30: 1213563332 | F30: =D30/E30 -> 0.17503857
C31: 2020 | D31: 205681950 | E31: 1019898963 | F31: =D31/E31 -> 0.20166895
C32: 2021 | D32: 298548048 | E32: 1010174017 | F32: =D32/E32 -> 0.29554121
C33: 2022 | D33: 306410502 | E33: 1000775865 | F33: =D33/E33 -> 0.30617295
A34: 7 | B34: SKLT | C34: 2018 | D34: 408057718435 | E34: 339236007000 | F34: =D34/E34 -> 1.2028727
C35: 2019 | D35: 410463595860 | E35: 380381947966 | F35: =D35/E35 -> 1.0790827
C36: 2020 | D36: 366908471713 | E36: 406954570727 | F36: =D36/E36 -> 0.90159565
C37: 2021 | D37: 347288021564 | E37: 541837229228 | F37: =D37/E37 -> 0.64094529
C38: 2022 | D38: 442535947408 | E38: 590753527421 | F38: =D38/E38 -> 0.7491042
A39: 8 | B39: CEKA | C39: 2018 | D39: 192308466864 | E39: 976647575842 | F39: =D39/E39 -> 0.19690672
C40: 2019 | D40: 261784845240 | E40: 1131294696834 | F40: =D40/E40 -> 0.23140287
C41: 2020 | D41: 305958833204 | E41: 1260714994864 | F41: =D41/E41 -> 0.24268676
...

Sheet X2
A1: Kebijakan Deviden (X2)
A3: No | B3: Kode | C3: Tahun | D3: Laba Bersih | E3: Deviden | F3: Kebijakan Deviden (X2)
A4: 1 | B4: ICBP | C4: 2018 | D4: 4658781 | E4: 2565620 | F4: =E4/D4 -> 0.55070629
C5: 2019 | D5: 5360029 | E5: 1597681 | F5: =E5/D5 -> 0.2980732
C6: 2020 | D6: 7418574 | E6: 2507310 | F6: =E6/D6 -> 0.33797735
C7: 2021 | D7: 7911943 | E7: 2507310 | F7: =E7/D7 -> 0.31690193
C8: 2022 | D8: 5722194 | E8: 2507310 | F8: =E8/D8 -> 0.43817284
A9: 2 | B9: INDF | C9: 2018 | D9: 4961851 | E9: 2651689 | F9: =E9/D9 -> 0.53441528
C10: 2019 | D10: 5902729 | E10: 1501453 | F10: =E10/D10 -> 0.2543659
C11: 2020 | D11: 8752066 | E11: 2440959 | F11: =E11/D11 -> 0.27890089
C12: 2021 | D12: 11229695 | E12: 2440959 | F12: =E12/D12 -> 0.21736646
C13: 2022 | D13: 9192569 | E13: 2440959 | F13: =E13/D13 -> 0.26553611
A14: 3 | B14: MYOR | C14: 2018 | D14: 1760434280304 | E14: 603684892575 | F14: =E14/D14 -> 0.34291816
C15: 2019 | D15: 2051404206764 | E15: 648402292025 | F15: =E15/D15 -> 0.31607729
C16: 2020 | D16: 2098168514645 | E16: 670760991750 | F16: =E16/D16 -> 0.31968881
C17: 2021 | D17: 1211052647953 | E17: 1162652385700 | F17: =E17/D17 -> 0.96003455
C18: 2022 | D18: 1970064538149 | E18: 469532694225 | F18: =E18/D18 -> 0.23833366
A19: 4 | B19: GOOD | C19: 2018 | D19: 425481597110 | E19: 183082141237 | F19: =E19/D19 -> 0.43029391
C20: 2019 | D20: 435766359480 | E20: 132379748022 | F20: =E20/D20 -> 0.30378607
C21: 2020 | D21: 245103761907 | E21: 213786027325 | F21: =E21/D21 -> 0.87222663
C22: 2021 | D22: 492637672186 | E22: 131923972638 | F22: =E22/D22 -> 0.26779108
C23: 2022 | D23: 521714035585 | E23: 221508548952 | F23: =E23/D23 -> 0.42457847
A24: 5 | B24: ROTI | C24: 2018 | D24: 127171436363 | E24: 36005365328 | F24: =E24/D24 -> 0.28312463
C25: 2019 | D25: 236518557420 | E25: 59724779679 | F25: =E25/D25 -> 0.25251625
C26: 2020 | D26: 168610282478 | E26: 149528741987 | F26: =E26/D26 -> 0.88683051
C27: 2021 | D27: 283602993676 | E27: 297289648543 | F27: =E27/D27 -> 1.0482599
C28: 2022 | D28: 432247722254 | E28: 346139578657 | F28: =E28/D28 -> 0.80078983
A29: 6 | B29: DLTA | C29: 2018 | D29: 338129985 | E29: 208171353 | F29: =E29/D29 -> 0.61565481
C30: 2019 | D30: 317815177 | E30: 382134244 | F30: =E30/D30 -> 1.2023788
C31: 2020 | D31: 123465762 | E31: 311711537 | F31: =E31/D31 -> 2.52468
C32: 2021 | D32: 187992998 | E32: 199764743 | F32: =E32/D32 -> 1.062618
C33: 2022 | D33: 230065807 | E33: 239785159 | F33: =E33/D33 -> 1.042246
A34: 7 | B34: SKLT | C34: 2018 | D34: 31954131252 | E34: 4351665150 | F34: =E34/D34 -> 0.13618474
C35: 2019 | D35: 44943627900 | E35: 5594998050 | F35: =E35/D35 -> 0.12448924
C36: 2020 | D36: 42520246722 | E36: 9324996750 | F36: =E36/D36 -> 0.21930721
C37: 2021 | D37: 84524160228 | E37: 9324996750 | F37: =E37/D37 -> 0.11032345
C38: 2022 | D38: 74865302076 | E38: 29841405600 | F38: =E38/D38 -> 0.39860128
A39: 8 | B39: CEKA | C39: 2018 | D39: 92649656775 | E39: 59500000000 | F39: =E39/D39 -> 0.64220421
C40: 2019 | D40: 215459200242 | E40: 59500000000 | F40: =E40/D40 -> 0.27615437
C41: 2020 | D41: 181812593992 | E41: 59500000000 | F41: =E41/D41 -> 0.32726006
...

Sheet X3
A1: Likuiditas (X3)
A3: No | B3: Kode | C3: Tahun | D3: Current Asset (Aset Lancar) | E3: Current Liabilities (Hutang Lancar) | F3: Likuiditas (X3)
A4: 1 | B4: ICBP | C4: 2018 | D4: 14121568 | E4: 7235398 | F4: =D4/E4 -> 1.9517334
C5: 2019 | D5: 16624925 | E5: 6556359 | F5: =D5/E5 -> 2.5356947
C6: 2020 | D6: 20716223 | E6: 9176164 | F6: =D6/E6 -> 2.2576125
C7: 2021 | D7: 33997637 | E7: 18896133 | F7: =D7/E7 -> 1.7991849
C8: 2022 | D8: 31070365 | E8: 10033935 | F8: =D8/E8 -> 3.0965284
A9: 2 | B9: INDF | C9: 2018 | D9: 33272618 | E9: 31204102 | F9: =D9/E9 -> 1.0662899
C10: 2019 | D10: 31403445 | E10: 24686862 | F10: =D10/E10 -> 1.2720712
C11: 2020 | D11: 38418238 | E11: 27975875 | F11: =D11/E11 -> 1.3732631
C12: 2021 | D12: 54183399 | E12: 40403404 | F12: =D12/E12 -> 1.3410602
C13: 2022 | D13: 54876668 | E13: 30725942 | F13: =D13/E13 -> 1.7860044
A14: 3 | B14: MYOR | C14: 2018 | D14: 12647858727872 | E14: 4764510387113 | F14: =D14/E14 -> 2.6545978
C15: 2019 | D15: 12776102781513 | E15: 3714359539201 | F15: =D15/E15 -> 3.4396516
C16: 2020 | D16: 12838729162094 | E16: 3475323711943 | F16: =D16/E16 -> 3.6942542
C17: 2021 | D17: 12969783874643 | E17: 5570773468770 | F17: =D17/E17 -> 2.3281837
C18: 2022 | D18: 14772623976128 | E18: 5636627301308 | F18: =D18/E18 -> 2.6208268
A19: 4 | B19: GOOD | C19: 2018 | D19: 1570545769306 | E19: 1328163043500 | F19: =D19/E19 -> 1.1824947
C20: 2019 | D20: 1999886108743 | E20: 1303881731637 | F20: =D20/E20 -> 1.5337941
C21: 2020 | D21: 2314323530275 | E21: 1321529767664 | F21: =D21/E21 -> 1.7512459
C22: 2021 | D22: 2613436417820 | E22: 1771339531925 | F22: =D22/E22 -> 1.4754012
C23: 2022 | D23: 3194327374948 | E23: 1835096804319 | F23: =D23/E23 -> 1.740686
A24: 5 | B24: ROTI | C24: 2018 | D24: 1876409299238 | E24: 525422150049 | F24: =D24/E24 -> 3.5712413
C25: 2019 | D25: 1874411044438 | E25: 1106938318565 | F25: =D25/E25 -> 1.6933293
C26: 2020 | D26: 1549617329468 | E26: 404567270700 | F26: =D26/E26 -> 3.8303082
C27: 2021 | D27: 1282057210341 | E27: 483213195704 | F27: =D27/E27 -> 2.6531916
C28: 2022 | D28: 1285672230703 | E28: 612417576293 | F28: =D28/E28 -> 2.0993392
A29: 6 | B29: DLTA | C29: 2018 | D29: 1384227944 | E29: 192299843 | F29: =D29/E29 -> 7.1982791
C30: 2019 | D30: 1292805083 | E30: 160587363 | F30: =D30/E30 -> 8.0504783
C31: 2020 | D31: 1103831856 | E31: 147207676 | F31: =D31/E31 -> 7.4984667
C32: 2021 | D32: 1174393432 | E32: 244206806 | F32: =D32/E32 -> 4.8090119
C33: 2022 | D33: 1165412820 | E33: 255354186 | F33: =D33/E33 -> 4.5639072
A34: 7 | B34: SKLT | C34: 2018 | D34: 356735670030 | E34: 291349105535 | F34: =D34/E34 -> 1.2244269
C35: 2019 | D35: 378352247338 | E35: 293281364781 | F35: =D35/E35 -> 1.2900658
C36: 2020 | D36: 379723220668 | E36: 247102759160 | F36: =D36/E36 -> 1.5367017
C37: 2021 | D37: 433383441542 | E37: 241664687612 | F37: =D37/E37 -> 1.7933255
C38: 2022 | D38: 543799195487 | E38: 333670108915 | F38: =D38/E38 -> 1.629751
A39: 8 | B39: CEKA | C39: 2018 | D39: 809166450672 | E39: 158255592250 | F39: =D39/E39 -> 5.1130354
C40: 2019 | D40: 1067652078121 | E40: 222440530626 | F40: =D40/E40 -> 4.7997192
C41: 2020 | D41: 1266586465994 | E41: 271641005590 | F41: =D41/E41 -> 4.6627219
...

Sheet X4
A1: Ukuran Perusahaan (X4)
A3: No | B3: Kode | C3: Tahun | D3: Total Aset | E3: Ukuran Perusahaan (X4)
A4: 1 | B4: ICBP | C4: 2018 | D4: 34367153 | E4: =LN(D4) -> 17.352612
C5: 2019 | D5: 38709314 | E5: =LN(D5) -> 17.471591
C6: 2020 | D6: 103588325 | E6: =LN(D6) -> 18.455935
C7: 2021 | D7: 118015311 | E7: =LN(D7) -> 18.586325
C8: 2022 | D8: 115305536 | E8: =LN(D8) -> 18.563096
A9: 2 | B9: INDF | C9: 2018 | D9: 96537796 | E9: =LN(D9) -> 18.385445
C10: 2019 | D10: 96198559 | E10: =LN(D10) -> 18.381925
C11: 2020 | D11: 163136516 | E11: =LN(D11) -> 18.910098
C12: 2021 | D12: 179271840 | E12: =LN(D12) -> 19.004414
C13: 2022 | D13: 180433300 | E13: =LN(D13) -> 19.010872
A14: 3 | B14: MYOR | C14: 2018 | D14: 17591706426634 | E14: =LN(D14) -> 30.498449
C15: 2019 | D15: 19037918806473 | E15: =LN(D15) -> 30.577454
C16: 2020 | D16: 19777500514550 | E16: =LN(D16) -> 30.615566
C17: 2021 | D17: 19917653265528 | E17: =LN(D17) -> 30.622628
C18: 2022 | D18: 22276160695411 | E18: =LN(D18) -> 30.734538
A19: 4 | B19: GOOD | C19: 2018 | D19: 4212408305683 | E19: =LN(D19) -> 29.069056
C20: 2019 | D20: 5063067672414 | E20: =LN(D20) -> 29.252994
C21: 2020 | D21: 6570969641033 | E21: =LN(D21) -> 29.513683
C22: 2021 | D22: 6766602280143 | E22: =LN(D22) -> 29.54302
C23: 2022 | D23: 7327371934290 | E23: =LN(D23) -> 29.622638
A24: 5 | B24: ROTI | C24: 2018 | D24: 4393810380883 | E24: =LN(D24) -> 29.111218
C25: 2019 | D25: 4682083844951 | E25: =LN(D25) -> 29.174764
C26: 2020 | D26: 4452166671985 | E26: =LN(D26) -> 29.124412
C27: 2021 | D27: 4191284422677 | E27: =LN(D27) -> 29.064028
C28: 2022 | D28: 4130321616083 | E28: =LN(D28) -> 29.049376
A29: 6 | B29: DLTA | C29: 2018 | D29: 1523517170 | E29: =LN(D29) -> 21.144287
C30: 2019 | D30: 1425983722 | E30: =LN(D30) -> 21.078128
C31: 2020 | D31: 1225580913 | E31: =LN(D31) -> 20.926681
C32: 2021 | D32: 1308722065 | E32: =LN(D32) -> 20.992317
C33: 2022 | D33: 1307186367 | E33: =LN(D33) -> 20.991143
A34: 7 | B34: SKLT | C34: 2018 | D34: 747293725435 | E34: =LN(D34) -> 27.339724
C35: 2019 | D35: 790845543826 | E35: =LN(D35) -> 27.396369
C36: 2020 | D36: 773863042440 | E36: =LN(D36) -> 27.374661
C37: 2021 | D37: 889125250792 | E37: =LN(D37) -> 27.513504
C38: 2022 | D38: 1033289474829 | E38: =LN(D38) -> 27.663768
A39: 8 | B39: CEKA | C39: 2018 | D39: 1168956042706 | E39: =LN(D39) -> 27.787132
C40: 2019 | D40: 1393079542074 | E40: =LN(D40) -> 27.962538
C41: 2020 | D41: 1566673828068 | E41: =LN(D41) -> 28.079976
...

Sheet Variabel Y
A1: Keputusan Investasi (Y)
A3: No | B3: Kode | C3: Tahun | D3: Total Aset | E3: Total Aset n-1 | F3: Keputusan Investasi (Y)
A4: 1 | B4: ICBP | C4: 2018 | D4: 34367153 | E4: 31619514 | F4: =(D4-E4)/E4 -> 0.08689694
C5: 2019 | D5: 38709314 | E5: 34367153 | F5: =(D5-E5)/E5 -> 0.12634625
C6: 2020 | D6: 103588325 | E6: 38709314 | F6: =(D6-E6)/E6 -> 1.6760569
C7: 2021 | D7: 118015311 | E7: 103588325 | F7: =(D7-E7)/E7 -> 0.13927232
C8: 2022 | D8: 115305536 | E8: 118015311 | F8: =(D8-E8)/E8 -> -0.022961216
A9: 2 | B9: INDF | C9: 2018 | D9: 96537796 | E9: 88400877 | F9: =(D9-E9)/E9 -> 0.092045682
C10: 2019 | D10: 96198559 | E10: 96537796 | F10: =(D10-E10)/E10 -> -0.003514033
C11: 2020 | D11: 163136516 | E11: 96198559 | F11: =(D11-E11)/E11 -> 0.69583118
C12: 2021 | D12: 179271840 | E12: 163136516 | F12: =(D12-E12)/E12 -> 0.098906881
C13: 2022 | D13: 180433300 | E13: 179271840 | F13: =(D13-E13)/E13 -> 0.0064787643
A14: 3 | B14: MYOR | C14: 2018 | D14: 17591706426634 | E14: 14915849800251 | F14: =(D14-E14)/E14 -> 0.17939686
C15: 2019 | D15: 19037918806473 | E15: 17591706426634 | F15: =(D15-E15)/E15 -> 0.082209897
C16: 2020 | D16: 19777500514550 | E16: 19037918806473 | F16: =(D16-E16)/E16 -> 0.038847823
C17: 2021 | D17: 19917653265528 | E17: 19777500514550 | F17: =(D17-E17)/E17 -> 0.0070864744
C18: 2022 | D18: 22276160695411 | E18: 19917653265528 | F18: =(D18-E18)/E18 -> 0.11841292
A19: 4 | B19: GOOD | C19: 2018 | D19: 4212408305683 | E19: 3564218091628 | F19: =(D19-E19)/E19 -> 0.18186042
C20: 2019 | D20: 5063067672414 | E20: 4212408305683 | F20: =(D20-E20)/E20 -> 0.20194134
C21: 2020 | D21: 6570969641033 | E21: 5063067672414 | F21: =(D21-E21)/E21 -> 0.29782378
C22: 2021 | D22: 6766602280143 | E22: 6570969641033 | F22: =(D22-E22)/E22 -> 0.029772263
C23: 2022 | D23: 7327371934290 | E23: 6766602280143 | F23: =(D23-E23)/E23 -> 0.082873151
A24: 5 | B24: ROTI | C24: 2018 | D24: 4393810380883 | E24: 4559573709411 | F24: =(D24-E24)/E24 -> -0.036355006
C25: 2019 | D25: 4682083844951 | E25: 4393810380883 | F25: =(D25-E25)/E25 -> 0.065608991
C26: 2020 | D26: 4452166671985 | E26: 4682083844951 | F26: =(D26-E26)/E26 -> -0.049105736
C27: 2021 | D27: 4191284422677 | E27: 4452166671985 | F27: =(D27-E27)/E27 -> -0.058596694
C28: 2022 | D28: 4130321616083 | E28: 4191284422677 | F28: =(D28-E28)/E28 -> -0.014545137
A29: 6 | B29: DLTA | C29: 2018 | D29: 1523517170 | E29: 1340842765 | F29: =(D29-E29)/E29 -> 0.1362385
C30: 2019 | D30: 1425983722 | E30: 1523517170 | F30: =(D30-E30)/E30 -> -0.064018608
C31: 2020 | D31: 1225580913 | E31: 1425983722 | F31: =(D31-E31)/E31 -> -0.14053653
C32: 2021 | D32: 1308722065 | E32: 1225580913 | F32: =(D32-E32)/E32 -> 0.067838158
C33: 2022 | D33: 1307186367 | E33: 1308722065 | F33: =(D33-E33)/E33 -> -0.0011734333
A34: 7 | B34: SKLT | C34: 2018 | D34: 747293725435 | E34: 636284210210 | F34: =(D34-E34)/E34 -> 0.1744653
C35: 2019 | D35: 790845543826 | E35: 747293725435 | F35: =(D35-E35)/E35 -> 0.058279385
C36: 2020 | D36: 773863042440 | E36: 790845543826 | F36: =(D36-E36)/E36 -> -0.021473854
C37: 2021 | D37: 889125250792 | E37: 773863042440 | F37: =(D37-E37)/E37 -> 0.14894394
C38: 2022 | D38: 1033289474829 | E38: 889125250792 | F38: =(D38-E38)/E38 -> 0.16214164
A39: 8 | B39: CEKA | C39: 2018 | D39: 1168956042706 | E39: 1392636444501 | F39: =(D39-E39)/E39 -> -0.16061651
C40: 2019 | D40: 1393079542074 | E40: 1168956042706 | F40: =(D40-E40)/E40 -> 0.19172962
C41: 2020 | D41: 1566673828068 | E41: 1393079542074 | F41: =(D41-E41)/E41 -> 0.1246119
...

Sheet Moderasi
A1: Kinerja Keuangan (M)
A3: No | B3: Kode | C3: Tahun | D3: Total Aset | E3: Laba Bersih | F3: Kinerja Keuangan (M)
A4: 1 | B4: ICBP | C4: 2018 | D4: 34367153 | E4: 4658781 | F4: =(E4/D4)*100 -> 13.555912
C5: 2019 | D5: 38709314 | E5: 5360029 | F5: =(E5/D5)*100 -> 13.846872
C6: 2020 | D6: 103588325 | E6: 7418574 | F6: =(E6/D6)*100 -> 7.1615928
C7: 2021 | D7: 118015311 | E7: 7911943 | F7: =(E7/D7)*100 -> 6.7041665
C8: 2022 | D8: 115305536 | E8: 5722194 | F8: =(E8/D8)*100 -> 4.962636
A9: 2 | B9: INDF | C9: 2018 | D9: 96537796 | E9: 4961851 | F9: =(E9/D9)*100 -> 5.1398014
C10: 2019 | D10: 96198559 | E10: 5902729 | F10: =(E10/D10)*100 -> 6.1359848
C11: 2020 | D11: 163136516 | E11: 8752066 | F11: =(E11/D11)*100 -> 5.3648724
C12: 2021 | D12: 179271840 | E12: 11229695 | F12: =(E12/D12)*100 -> 6.2640597
C13: 2022 | D13: 180433300 | E13: 9192569 | F13: =(E13/D13)*100 -> 5.0947187
A14: 3 | B14: MYOR | C14: 2018 | D14: 17591706426634 | E14: 1760434280304 | F14: =(E14/D14)*100 -> 10.007183
C15: 2019 | D15: 19037918806473 | E15: 2051404206764 | F15: =(E15/D15)*100 -> 10.77536
C16: 2020 | D16: 19777500514550 | E16: 2098168514645 | F16: =(E16/D16)*100 -> 10.608866
C17: 2021 | D17: 19917653265528 | E17: 1211052647953 | F17: =(E17/D17)*100 -> 6.0802979
C18: 2022 | D18: 22276160695411 | E18: 1970064538149 | F18: =(E18/D18)*100 -> 8.8438244
A19: 4 | B19: GOOD | C19: 2018 | D19: 4212408305683 | E19: 425481597110 | F19: =(E19/D19)*100 -> 10.100673
C20: 2019 | D20: 5063067672414 | E20: 435766359480 | F20: =(E20/D20)*100 -> 8.6067655
C21: 2020 | D21: 6570969641033 | E21: 245103761907 | F21: =(E21/D21)*100 -> 3.7301004
C22: 2021 | D22: 6766602280143 | E22: 492637672186 | F22: =(E22/D22)*100 -> 7.280429
C23: 2022 | D23: 7327371934290 | E23: 521714035585 | F23: =(E23/D23)*100 -> 7.1200703
A24: 5 | B24: ROTI | C24: 2018 | D24: 4393810380883 | E24: 127171436363 | F24: =(E24/D24)*100 -> 2.8943315
C25: 2019 | D25: 4682083844951 | E25: 236518557420 | F25: =(E25/D25)*100 -> 5.051566
C26: 2020 | D26: 4452166671985 | E26: 168610282478 | F26: =(E26/D26)*100 -> 3.7871512
C27: 2021 | D27: 4191284422677 | E27: 283602993676 | F27: =(E27/D27)*100 -> 6.7664936
C28: 2022 | D28: 4130321616083 | E28: 432247722254 | F28: =(E28/D28)*100 -> 10.465232
A29: 6 | B29: DLTA | C29: 2018 | D29: 1523517170 | E29: 338129985 | F29: =(E29/D29)*100 -> 22.194038
C30: 2019 | D30: 1425983722 | E30: 317815177 | F30: =(E30/D30)*100 -> 22.287434
C31: 2020 | D31: 1225580913 | E31: 123465762 | F31: =(E31/D31)*100 -> 10.07406
C32: 2021 | D32: 1308722065 | E32: 187992998 | F32: =(E32/D32)*100 -> 14.364624
C33: 2022 | D33: 1307186367 | E33: 230065807 | F33: =(E33/D33)*100 -> 17.600077
A34: 7 | B34: SKLT | C34: 2018 | D34: 747293725435 | E34: 31954131252 | F34: =(E34/D34)*100 -> 4.2759801
C35: 2019 | D35: 790845543826 | E35: 44943627900 | F35: =(E35/D35)*100 -> 5.6829843
C36: 2020 | D36: 773863042440 | E36: 42520246722 | F36: =(E36/D36)*100 -> 5.4945442
C37: 2021 | D37: 889125250792 | E37: 84524160228 | F37: =(E37/D37)*100 -> 9.5064402
C38: 2022 | D38: 1033289474829 | E38: 74865302076 | F38: =(E38/D38)*100 -> 7.2453368
A39: 8 | B39: CEKA | C39: 2018 | D39: 1168956042706 | E39: 92649656775 | F39: =(E39/D39)*100 -> 7.9258461
C40: 2019 | D40: 1393079542074 | E40: 215459200242 | F40: =(E40/D40)*100 -> 15.466396
C41: 2020 | D41: 1566673828068 | E41: 181812593992 | F41: =(E41/D41)*100 -> 11.605006
...

Sheet Sheet1
A1: Kode | B1: Tahun | C1: SM | D1: KD | E1: Lik | F1: UP | G1: KK | H1: KI | I1: SM_KK | J1: KD_KK | K1: Lik_KK | L1: UP_KK
A2: ICBP | B2: 2018 | C2: 0.51349478 | D2: 0.55070629 | E2: 1.9517334 | F2: 17.352612 | G2: 13.555912 | H2: 0.08689694 | I2: =C2*G2 -> 6.96089 | J2: =D2*G2 -> 7.465326 | K2: =E2*G2 -> 26.457526 | L2: =F2*G2 -> 235.23048
A3: ICBP | B3: 2019 | C3: 0.45135777 | D3: 0.2980732 | E3: 2.5356947 | F3: 17.471591 | G3: 13.846872 | H3: 0.12634625 | I3: =C3*G3 -> 6.2498931 | J3: =D3*G3 -> 4.1273813 | K3: =E3*G3 -> 35.111439 | L3: =F3*G3 -> 241.92687
A4: ICBP | B4: 2020 | C4: 1.0586712 | D4: 0.33797735 | E4: 2.2576125 | F4: 18.455935 | G4: 7.1615928 | H4: 1.6760569 | I4: =C4*G4 -> 7.5817718 | J4: =D4*G4 -> 2.4204562 | K4: =E4*G4 -> 16.168102 | L4: =F4*G4 -> 132.17389
A5: ICBP | B5: 2021 | C5: 1.1480526 | D5: 0.31690193 | E5: 1.7991849 | F5: 18.586325 | G5: 6.7041665 | H5: 0.13927232 | I5: =C5*G5 -> 7.6967355 | J5: =D5*G5 -> 2.1245633 | K5: =E5*G5 -> 12.062035 | L5: =F5*G5 -> 124.60582
A6: ICBP | B6: 2022 | C6: 1.0062555 | D6: 0.43817284 | E6: 3.0965284 | F6: 18.563096 | G6: 4.962636 | H6: -0.022961216 | I6: =C6*G6 -> 4.9936797 | J6: =D6*G6 -> 2.1744923 | K6: =E6*G6 -> 15.366943 | L6: =F6*G6 -> 92.121888
A7: INDF | B7: 2018 | C7: 0.93397405 | D7: 0.53441528 | E7: 1.0662899 | F7: 18.385445 | G7: 5.1398014 | H7: 0.092045682 | I7: =C7*G7 -> 4.8004412 | J7: =D7*G7 -> 2.7467884 | K7: =E7*G7 -> 5.4805182 | L7: =F7*G7 -> 94.497537
A8: INDF | B8: 2019 | C8: 0.77479969 | D8: 0.2543659 | E8: 1.2720712 | F8: 18.381925 | G8: 6.1359848 | H8: -0.003514033 | I8: =C8*G8 -> 4.7541592 | J8: =D8*G8 -> 1.5607853 | K8: =E8*G8 -> 7.8054093 | L8: =F8*G8 -> 112.79121
A9: INDF | B9: 2020 | C9: 1.0614171 | D9: 0.27890089 | E9: 1.3732631 | F9: 18.910098 | G9: 5.3648724 | H9: 0.69583118 | I9: =C9*G9 -> 5.6943673 | J9: =D9*G9 -> 1.4962677 | K9: =E9*G9 -> 7.3673816 | L9: =F9*G9 -> 101.45026
A10: INDF | B10: 2021 | C10: 1.0609154 | D10: 0.21736646 | E10: 1.3410602 | F10: 19.004414 | G10: 6.2640597 | H10: 0.098906881 | I10: =C10*G10 -> 6.6456376 | J10: =D10*G10 -> 1.3615964 | K10: =E10*G10 -> 8.4004814 | L10: =F10*G10 -> 119.04478
A11: INDF | B11: 2022 | C11: 0.92723184 | D11: 0.26553611 | E11: 1.7860044 | F11: 19.010872 | G11: 5.0947187 | H11: 0.0064787643 | I11: =C11*G11 -> 4.7239854 | J11: =D11*G11 -> 1.3528318 | K11: =E11*G11 -> 9.09919 | L11: =F11*G11 -> 96.855043
A12: MYOR | B12: 2018 | C12: 1.0593052 | D12: 0.34291816 | E12: 2.6545978 | F12: 30.498449 | G12: 10.007183 | H12: 0.17939686 | I12: =C12*G12 -> 10.600661 | J12: =D12*G12 -> 3.4316449 | K12: =E12*G12 -> 26.565046 | L12: =F12*G12 -> 305.20356
A13: MYOR | B13: 2019 | C13: 0.92070558 | D13: 0.31607729 | E13: 3.4396516 | F13: 30.577454 | G13: 10.77536 | H13: 0.082209897 | I13: =C13*G13 -> 9.9209336 | J13: =D13*G13 -> 3.4058465 | K13: =E13*G13 -> 37.063483 | L13: =F13*G13 -> 329.48306
... A51: HOKI | B51: 2022 | C51: 0.21341418 | D51: 106.85092 | E51: 3.2690891 | F51: 27.422278 | G51: 0.011159693 | H51: -0.17817579 | I51: =C51*G51 -> 0.0023816368 | J51: =D51*G51 -> 1.1924235 | K51: =E51*G51 -> 0.036482031 | L51: =F51*G51 -> 0.3060242

Sheet Normalized
A1: Kode | B1: Tahun | C1: SM | D1: KD | E1: Lik | F1: UP | G1: KK | H1: KI | I1: SM_KK | J1: KD_KK | K1: Lik_KK | L1: UP_KK
A2: ICBP | B2: 2018 | C2: =SQRT(Sheet1!C2+0.5) -> 1.0067248 | D2: =SQRT(Sheet1!D2+0.5) -> 1.0250397 | E2: =SQRT(Sheet1!E2+0.5) -> 1.5658012 | F2: =SQRT(Sheet1!F2+0.5) -> 4.2252351 | G2: =SQRT(Sheet1!G2+0.5) -> 3.7491215 | H2: =SQRT(Sheet1!H2+0.5) -> 0.76609199 | I2: =SQRT(Sheet1!I2+0.5) -> 2.731463 | J2: =SQRT(Sheet1!J2+0.5) -> 2.8222909 | ... L2: =SQRT(Sheet1!L2+0.5) -> 15.353517
A3: ICBP | B3: 2019 | C3: =SQRT(Sheet1!C3+0.5) -> 0.97537571 | D3: =SQRT(Sheet1!D3+0.5) -> 0.89334943 | E3: =SQRT(Sheet1!E3+0.5) -> 1.7423245 | F3: =SQRT(Sheet1!F3+0.5) -> 4.2392913 | G3: =SQRT(Sheet1!G3+0.5) -> 3.7877264 | H3: =SQRT(Sheet1!H3+0.5) -> 0.7914204 | I3: =SQRT(Sheet1!I3+0.5) -> 2.5980556 | J3: =SQRT(Sheet1!J3+0.5) -> 2.1511349 | ... L3: =SQRT(Sheet1!L3+0.5) -> 15.570063
A4: ICBP | B4: 2020 | C4: =SQRT(Sheet1!C4+0.5) -> 1.2484675 | D4: =SQRT(Sheet1!D4+0.5) -> 0.91541103 | E4: =SQRT(Sheet1!E4+0.5) -> 1.6606061 | F4: =SQRT(Sheet1!F4+0.5) -> 4.3538414 | G4: =SQRT(Sheet1!G4+0.5) -> 2.7679582 | H4: =SQRT(Sheet1!H4+0.5) -> 1.4751464 | I4: =SQRT(Sheet1!I4+0.5) -> 2.8428457 | J4: =SQRT(Sheet1!J4+0.5) -> 1.7089342 | ... L4: =SQRT(Sheet1!L4+0.5) -> 11.518415
A5: ICBP | B5: 2021 | C5: =SQRT(Sheet1!C5+0.5) -> 1.283765 | D5: =SQRT(Sheet1!D5+0.5) -> 0.90382627 | E5: =SQRT(Sheet1!E5+0.5) -> 1.5163063 | F5: =SQRT(Sheet1!F5+0.5) -> 4.3687899 | G5: =SQRT(Sheet1!G5+0.5) -> 2.6840579 | H5: =SQRT(Sheet1!H5+0.5) -> 0.79954507 | I5: =SQRT(Sheet1!I5+0.5) -> 2.8629942 | J5: =SQRT(Sheet1!J5+0.5) -> 1.6200504 | ... L5: =SQRT(Sheet1!L5+0.5) -> 11.185071 | O5: =FINV(0.05,5,44) -> 2.4270401
A6: ICBP | B6: 2022 | C6: =SQRT(Sheet1!C6+0.5) -> 1.227296 | D6: =SQRT(Sheet1!D6+0.5) -> 0.96859323 | E6: =SQRT(Sheet1!E6+0.5) -> 1.8964515 | F6: =SQRT(Sheet1!F6+0.5) -> 4.3661306 | G6: =SQRT(Sheet1!G6+0.5) -> 2.3372283 | H6: =SQRT(Sheet1!H6+0.5) -> 0.69067994 | I6: =SQRT(Sheet1!I6+0.5) -> 2.34386 | J6: =SQRT(Sheet1!J6+0.5) -> 1.6353875 | ... L6: =SQRT(Sheet1!L6+0.5) -> 9.6240266 | O6: =TINV(0.05,44) -> 2.0153676
A7: INDF | B7: 2018 | C7: =SQRT(Sheet1!C7+0.5) -> 1.1974866 | D7: =SQRT(Sheet1!D7+0.5) -> 1.0170621 | E7: =SQRT(Sheet1!E7+0.5) -> 1.251515 | F7: =SQRT(Sheet1!F7+0.5) -> 4.3457387 | G7: =SQRT(Sheet1!G7+0.5) -> 2.3748266 | H7: =SQRT(Sheet1!H7+0.5) -> 0.76944505 | I7: =SQRT(Sheet1!I7+0.5) -> 2.3022687 | J7: =SQRT(Sheet1!J7+0.5) -> 1.8018847 | ... L7: =SQRT(Sheet1!L7+0.5) -> 9.746668
A8: INDF | B8: 2019 | C8: =SQRT(Sheet1!C8+0.5) -> 1.1290703 | D8: =SQRT(Sheet1!D8+0.5) -> 0.8685424 | E8: =SQRT(Sheet1!E8+0.5) -> 1.3311916 | F8: =SQRT(Sheet1!F8+0.5) -> 4.3453337 | G8: =SQRT(Sheet1!G8+0.5) -> 2.5760405 | H8: =SQRT(Sheet1!H8+0.5) -> 0.7046176 | I8: =SQRT(Sheet1!I8+0.5) -> 2.2921953 | J8: =SQRT(Sheet1!J8+0.5) -> 1.4355436 | ... L8: =SQRT(Sheet1!L8+0.5) -> 10.643834
A9: INDF | B9: 2020 | C9: =SQRT(Sheet1!C9+0.5) -> 1.2495668 | D9: =SQRT(Sheet1!D9+0.5) -> 0.88255362 | E9: =SQRT(Sheet1!E9+0.5) -> 1.368672 | F9: =SQRT(Sheet1!F9+0.5) -> 4.4056893 | G9: =SQRT(Sheet1!G9+0.5) -> 2.4217499 | H9: =SQRT(Sheet1!H9+0.5) -> 1.0935407 | I9: =SQRT(Sheet1!I9+0.5) -> 2.4888486 | J9: =SQRT(Sheet1!J9+0.5) -> 1.4128934 | ... L9: =SQRT(Sheet1!L9+0.5) -> 10.097042
A10: INDF | B10: 2021 | C10: =SQRT(Sheet1!C10+0.5) -> 1.249366 | D10: =SQRT(Sheet1!D10+0.5) -> 0.84697488 | E10: =SQRT(Sheet1!E10+0.5) -> 1.3568568 | F10: =SQRT(Sheet1!F10+0.5) -> 4.4163802 | G10: =SQRT(Sheet1!G10+0.5) -> 2.6007806 | H10: =SQRT(Sheet1!H10+0.5) -> 0.77389074 | I10: =SQRT(Sheet1!I10+0.5) -> 2.6731326 | J10: =SQRT(Sheet1!J10+0.5) -> 1.3644033 | ... L10: =SQRT(Sheet1!L10+0.5) -> 10.933654
A11: INDF | B11: 2022 | C11: =SQRT(Sheet1!C11+0.5) -> 1.1946681 | D11: =SQRT(Sheet1!D11+0.5) -> 0.8749492 | E11: =SQRT(Sheet1!E11+0.5) -> 1.5119538 | F11: =SQRT(Sheet1!F11+0.5) -> 4.4171112 | G11: =SQRT(Sheet1!G11+0.5) -> 2.3653158 | H11: =SQRT(Sheet1!H11+0.5) -> 0.71167321 | I11: =SQRT(Sheet1!I11+0.5) -> 2.2856039 | J11: =SQRT(Sheet1!J11+0.5) -> 1.3611876 | ... L11: =SQRT(Sheet1!L11+0.5) -> 9.8668659
A12: MYOR | B12: 2018 | C12: =SQRT(Sheet1!C12+0.5) -> 1.2487214 | D12: =SQRT(Sheet1!D12+0.5) -> 0.91810575 | E12: =SQRT(Sheet1!E12+0.5) -> 1.7761187 | F12: =SQRT(Sheet1!F12+0.5) -> 5.567625 | G12: =SQRT(Sheet1!G12+0.5) -> 3.2414785 | H12: =SQRT(Sheet1!H12+0.5) -> 0.82425534 | I12: =SQRT(Sheet1!I12+0.5) -> 3.3317655 | J12: =SQRT(Sheet1!J12+0.5) -> 1.9828376 | ... L12: =SQRT(Sheet1!L12+0.5) -> 17.484381
A13: MYOR | B13: 2019 | C13: =SQRT(Sheet1!C13+0.5) -> 1.1919335 | D13: =SQRT(Sheet1!D13+0.5) -> 0.90336997 | E13: =SQRT(Sheet1!E13+0.5) -> 1.9848556 | F13: =SQRT(Sheet1!F13+0.5) -> 5.5747156 | G13: =SQRT(Sheet1!G13+0.5) -> 3.3578802 | H13: =SQRT(Sheet1!H13+0.5) -> 0.7630268 | I13: =SQRT(Sheet1!I13+0.5) -> 3.2281471 | J13: =SQRT(Sheet1!J13+0.5) -> 1.9763215 | ... L13: =SQRT(Sheet1!L13+0.5) -> 18.165436
A14: MYOR | B14: 2020 | C14: =SQRT(Sheet1!C14+0.5) -> 1.1201124 | D14: =SQRT(Sheet1!D14+0.5) -> 0.90536667 | E14: =SQRT(Sheet1!E14+0.5) -> 2.0479878 | F14: =SQRT(Sheet1!F14+0.5) -> 5.5781328 | G14: =SQRT(Sheet1!G14+0.5) -> 3.3329965 | H14: =SQRT(Sheet1!H14+0.5) -> 0.73406255 | I14: =SQRT(Sheet1!I14+0.5) -> 2.9165045 | J14: =SQRT(Sheet1!J14+0.5) -> 1.9726976 | ... L14: =SQRT(Sheet1!L14+0.5) -> 18.035976
A15: MYOR | B15: 2021 | C15: =SQRT(Sheet1!C15+0.5) -> 1.1195132 | D15: =SQRT(Sheet1!D15+0.5) -> 1.2083189 | E15: =SQRT(Sheet1!E15+0.5) -> 1.6817205 | F15: =SQRT(Sheet1!F15+0.5) -> 5.5787658 | G15: =SQRT(Sheet1!G15+0.5) -> 2.5652091 | H15: =SQRT(Sheet1!H15+0.5) -> 0.71210005 | I15: =SQRT(Sheet1!I15+0.5) -> 2.2539626 | J15: =SQRT(Sheet1!J15+0.5) -> 2.5173987 | ... L15: =SQRT(Sheet1!L15+0.5) -> 13.663627
A16: MYOR | B16: 2022 | C16: =SQRT(Sheet1!C16+0.5) -> 1.1115848 | D16: =SQRT(Sheet1!D16+0.5) -> 0.85926344 | E16: =SQRT(Sheet1!E16+0.5) -> 1.7665862 | F16: =SQRT(Sheet1!F16+0.5) -> 5.5887868 | G16: =SQRT(Sheet1!G16+0.5) -> 3.056767 | H16: =SQRT(Sheet1!H16+0.5) -> 0.78639234 | I16: =SQRT(Sheet1!I16+0.5) -> 2.6468283 | J16: =SQRT(Sheet1!J16+0.5) -> 1.6148625 | ... L16: =SQRT(Sheet1!L16+0.5) -> 16.501844
A17: GOOD | B17: 2018 | C17: =SQRT(Sheet1!C17+0.5) -> 1.0918481 | D17: =SQRT(Sheet1!D17+0.5) -> 0.96451745 | E17: =SQRT(Sheet1!E17+0.5) -> 1.2971101 | F17: =SQRT(Sheet1!F17+0.5) -> 5.4377436 | G17: =SQRT(Sheet1!G17+0.5) -> 3.2558675 | H17: =SQRT(Sheet1!H17+0.5) -> 0.8257484 | I17: =SQRT(Sheet1!I17+0.5) -> 2.7369694 | J17: =SQRT(Sheet1!J17+0.5) -> 2.2014219 | ... L17: =SQRT(Sheet1!L17+0.5) -> 17.149841
A18: GOOD | B18: 2019 | C18: =SQRT(Sheet1!C18+0.5) -> 1.1535956 | D18: =SQRT(Sheet1!D18+0.5) -> 0.89654117 | E18: =SQRT(Sheet1!E18+0.5) -> 1.4261115 | F18: =SQRT(Sheet1!F18+0.5) -> 5.4546305 | G18: =SQRT(Sheet1!G18+0.5) -> 3.0177418 | H18: =SQRT(Sheet1!H18+0.5) -> 0.83781939 | I18: =SQRT(Sheet1!I18+0.5) -> 2.765927 | J18: =SQRT(Sheet1!J18+0.5) -> 1.7648273 | ... L18: =SQRT(Sheet1!L18+0.5) -> 15.883125
... A51: HOKI | B51: 2022 | C51: =SQRT(Sheet1!C51+0.5) -> 0.84463849 | D51: =SQRT(Sheet1!D51+0.5) -> 10.361029 | E51: =SQRT(Sheet1!E51+0.5) -> 1.9414142 | F51: =SQRT(Sheet1!F51+0.5) -> 5.2841535 | G51: =SQRT(Sheet1!G51+0.5) -> 0.71495433 | H51: =SQRT(Sheet1!H51+0.5) -> 0.56729552 | I51: =SQRT(Sheet1!I51+0.5) -> 0.70878885 | J51: =SQRT(Sheet1!J51+0.5) -> 1.3009318 | ... L51: =SQRT(Sheet1!L51+0.5) -> 0.89778851
